INFO: Starting training:
        Epochs:          1
        Batch size:      1
        Learning rate:   1e-05
        Training size:   9000
        Validation size: 1000
        Checkpoints:     True
        Device:          cuda
        Images scaling:  0.5
        Mixed Precision: False







































Epoch 1/1:   5%|██████                                                                                                           | 485/9000 [01:28<25:51,  5.49img/s, loss (batch)=0.568]
Traceback (most recent call last):
  File "train.py", line 191, in <module>
    train_net(net=net,
  File "train.py", line 79, in train_net
    for batch in train_loader:
  File "C:\Users\yunjc\anaconda3\envs\dl_env\lib\site-packages\torch\utils\data\dataloader.py", line 521, in __next__
    data = self._next_data()
  File "C:\Users\yunjc\anaconda3\envs\dl_env\lib\site-packages\torch\utils\data\dataloader.py", line 1203, in _next_data
    return self._process_data(data)
  File "C:\Users\yunjc\anaconda3\envs\dl_env\lib\site-packages\torch\utils\data\dataloader.py", line 1229, in _process_data
    data.reraise()
  File "C:\Users\yunjc\anaconda3\envs\dl_env\lib\site-packages\torch\_utils.py", line 434, in reraise
    raise exception
TypeError: Caught TypeError in DataLoader worker process 1.
Original Traceback (most recent call last):
  File "C:\Users\yunjc\anaconda3\envs\dl_env\lib\site-packages\torch\utils\data\_utils\worker.py", line 287, in _worker_loop
    data = fetcher.fetch(index)
  File "C:\Users\yunjc\anaconda3\envs\dl_env\lib\site-packages\torch\utils\data\_utils\fetch.py", line 49, in fetch
    data = [self.dataset[idx] for idx in possibly_batched_index]
  File "C:\Users\yunjc\anaconda3\envs\dl_env\lib\site-packages\torch\utils\data\_utils\fetch.py", line 49, in <listcomp>
    data = [self.dataset[idx] for idx in possibly_batched_index]
  File "C:\Users\yunjc\anaconda3\envs\dl_env\lib\site-packages\torch\utils\data\dataset.py", line 363, in __getitem__
    return self.dataset[self.indices[idx]]
  File "C:\Users\yunjc\_python_jupyter\bupyeonggu\bp_road_crack_detection\_model_test\Pytorch-UNet-master\utils\crack_data_loading.py", line 104, in __getitem__
    annot = self.load(ann_file[0])
  File "C:\Users\yunjc\_python_jupyter\bupyeonggu\bp_road_crack_detection\_model_test\Pytorch-UNet-master\utils\crack_data_loading.py", line 79, in load
    temp_int = np.apply_along_axis(np.int32, arr=temp, axis=0)
  File "<__array_function__ internals>", line 5, in apply_along_axis
  File "C:\Users\yunjc\anaconda3\envs\dl_env\lib\site-packages\numpy\lib\shape_base.py", line 379, in apply_along_axis
    res = asanyarray(func1d(inarr_view[ind0], *args, **kwargs))
TypeError: int() argument must be a string, a bytes-like object or a number, not 'NoneType'