INFO: Starting training:
        Epochs:          5
        Batch size:      1
        Learning rate:   1e-05
        Training size:   9000
        Validation size: 1000
        Checkpoints:     True
        Device:          cpu
        Images scaling:  0.4
        Mixed Precision: False
Epoch 1/5:   0%|                                                                                                                                               | 0/9000 [00:07<?, ?img/s]
Traceback (most recent call last):
  File "C:\Users\yunjc\_python_jupyter\bupyeonggu\bp_road_crack_detection\_model_test\Pytorch-UNet-master\train.py", line 191, in <module>
    train_net(net=net,
  File "C:\Users\yunjc\_python_jupyter\bupyeonggu\bp_road_crack_detection\_model_test\Pytorch-UNet-master\train.py", line 79, in train_net
    for batch in train_loader:
  File "C:\Users\yunjc\anaconda3\lib\site-packages\torch\utils\data\dataloader.py", line 521, in __next__
    data = self._next_data()
  File "C:\Users\yunjc\anaconda3\lib\site-packages\torch\utils\data\dataloader.py", line 1203, in _next_data
    return self._process_data(data)
  File "C:\Users\yunjc\anaconda3\lib\site-packages\torch\utils\data\dataloader.py", line 1229, in _process_data
    data.reraise()
  File "C:\Users\yunjc\anaconda3\lib\site-packages\torch\_utils.py", line 434, in reraise
    raise exception
AttributeError: Caught AttributeError in DataLoader worker process 0.
Original Traceback (most recent call last):
  File "C:\Users\yunjc\anaconda3\lib\site-packages\torch\utils\data\_utils\worker.py", line 287, in _worker_loop
    data = fetcher.fetch(index)
  File "C:\Users\yunjc\anaconda3\lib\site-packages\torch\utils\data\_utils\fetch.py", line 49, in fetch
    data = [self.dataset[idx] for idx in possibly_batched_index]
  File "C:\Users\yunjc\anaconda3\lib\site-packages\torch\utils\data\_utils\fetch.py", line 49, in <listcomp>
    data = [self.dataset[idx] for idx in possibly_batched_index]
  File "C:\Users\yunjc\anaconda3\lib\site-packages\torch\utils\data\dataset.py", line 363, in __getitem__
    return self.dataset[self.indices[idx]]
  File "C:\Users\yunjc\_python_jupyter\bupyeonggu\bp_road_crack_detection\_model_test\Pytorch-UNet-master\utils\crack_data_loading.py", line 100, in __getitem__
    annot = self.load(ann_file[0])
  File "C:\Users\yunjc\_python_jupyter\bupyeonggu\bp_road_crack_detection\_model_test\Pytorch-UNet-master\utils\crack_data_loading.py", line 72, in load
    lbl = np.zero((720,1280), np.uint8)
  File "C:\Users\yunjc\anaconda3\lib\site-packages\numpy\__init__.py", line 303, in __getattr__
    raise AttributeError("module {!r} has no attribute "
AttributeError: module 'numpy' has no attribute 'zero'