INFO: Starting training:
        Epochs:          5
        Batch size:      1
        Learning rate:   1e-05
        Training size:   9000
        Validation size: 1000
        Checkpoints:     True
        Device:          cuda
        Images scaling:  0.4
        Mixed Precision: True
Epoch 1/5:   0%|                                                                                                                                           | 0/9000 [00:05<?, ?img/s]
Traceback (most recent call last):
  File "train.py", line 185, in <module>
    train_net(net=net,
  File "train.py", line 80, in train_net
    for batch in train_loader:
  File "C:\Users\yunjc\anaconda3\envs\dl_env\lib\site-packages\torch\utils\data\dataloader.py", line 521, in __next__
    data = self._next_data()
  File "C:\Users\yunjc\anaconda3\envs\dl_env\lib\site-packages\torch\utils\data\dataloader.py", line 1203, in _next_data
    return self._process_data(data)
  File "C:\Users\yunjc\anaconda3\envs\dl_env\lib\site-packages\torch\utils\data\dataloader.py", line 1229, in _process_data
    data.reraise()
  File "C:\Users\yunjc\anaconda3\envs\dl_env\lib\site-packages\torch\_utils.py", line 434, in reraise
    raise exception
AssertionError: Caught AssertionError in DataLoader worker process 0.
Original Traceback (most recent call last):
  File "C:\Users\yunjc\anaconda3\envs\dl_env\lib\site-packages\torch\utils\data\_utils\worker.py", line 287, in _worker_loop
    data = fetcher.fetch(index)
  File "C:\Users\yunjc\anaconda3\envs\dl_env\lib\site-packages\torch\utils\data\_utils\fetch.py", line 49, in fetch
    data = [self.dataset[idx] for idx in possibly_batched_index]
  File "C:\Users\yunjc\anaconda3\envs\dl_env\lib\site-packages\torch\utils\data\_utils\fetch.py", line 49, in <listcomp>
    data = [self.dataset[idx] for idx in possibly_batched_index]
  File "C:\Users\yunjc\anaconda3\envs\dl_env\lib\site-packages\torch\utils\data\dataset.py", line 363, in __getitem__
    return self.dataset[self.indices[idx]]
  File "C:\Users\yunjc\_python_jupyter\bupyeonggu\bp_road_crack_detection\_model_test\Pytorch-UNet-master\utils\crack_data_loading.py", line 69, in __getitem__
    assert len(ann_file)==1, f"어노테이션이 없거나, 여러 개의 ID를 지녔습니다. {name}: {ann_file}"
AssertionError: 어노테이션이 없거나, 여러 개의 ID를 지녔습니다. V0F_HY_6421_20201221_160400_E_CH1_Seoul_Sun_Frontback_Day_66415: []