2022-02-04 16:05:57,540 INFO    MainThread:5500 [wandb_setup.py:_flush():75] Loading settings from C:\Users\chank\.config\wandb\settings
2022-02-04 16:05:57,541 INFO    MainThread:5500 [wandb_setup.py:_flush():75] Loading settings from G:\내 드라이브\인턴\bp_street_crack_dectection\1_모델링\test_unet\wandb\settings
2022-02-04 16:05:57,541 INFO    MainThread:5500 [wandb_setup.py:_flush():75] Loading settings from environment variables: {}
2022-02-04 16:05:57,541 INFO    MainThread:5500 [wandb_setup.py:_flush():75] Inferring run settings from compute environment: {'program_relpath': '1_모델링\\test_unet\\train.py', 'program': 'G:/내 드라이브/인턴/bp_street_crack_dectection/1_모델링/test_unet/train.py'}
2022-02-04 16:05:57,541 INFO    MainThread:5500 [wandb_setup.py:_flush():75] Applying login settings: {'anonymous': 'must'}
2022-02-04 16:05:57,541 INFO    MainThread:5500 [wandb_init.py:_log_setup():386] Logging user logs to G:\내 드라이브\인턴\bp_street_crack_dectection\1_모델링\test_unet\wandb\run-20220204_160557-1vlvtjku\logs\debug.log
2022-02-04 16:05:57,542 INFO    MainThread:5500 [wandb_init.py:_log_setup():387] Logging internal logs to G:\내 드라이브\인턴\bp_street_crack_dectection\1_모델링\test_unet\wandb\run-20220204_160557-1vlvtjku\logs\debug-internal.log
2022-02-04 16:05:57,542 INFO    MainThread:5500 [wandb_init.py:init():420] calling init triggers
2022-02-04 16:05:57,542 INFO    MainThread:5500 [wandb_init.py:init():427] wandb.init called with sweep_config: {}
config: {}
2022-02-04 16:05:57,542 INFO    MainThread:5500 [wandb_init.py:init():471] starting backend
2022-02-04 16:05:57,542 INFO    MainThread:5500 [backend.py:_multiprocessing_setup():101] multiprocessing start_methods=spawn, using: spawn
2022-02-04 16:05:57,546 INFO    MainThread:5500 [backend.py:ensure_launched():219] starting backend process...
2022-02-04 16:05:58,160 INFO    MainThread:5500 [backend.py:ensure_launched():225] started backend process with pid: 16892
2022-02-04 16:05:58,162 INFO    MainThread:5500 [wandb_init.py:init():480] backend started and connected
2022-02-04 16:05:58,163 INFO    MainThread:5500 [wandb_init.py:init():550] updated telemetry
2022-02-04 16:05:58,202 INFO    MainThread:5500 [wandb_init.py:init():581] communicating current version
2022-02-04 16:05:58,710 INFO    MainThread:5500 [wandb_init.py:init():586] got version response 
2022-02-04 16:05:58,710 INFO    MainThread:5500 [wandb_init.py:init():596] communicating run to backend with 30 second timeout
2022-02-04 16:05:59,164 INFO    MainThread:5500 [wandb_init.py:init():624] starting run threads in backend
2022-02-04 16:06:00,704 INFO    MainThread:5500 [wandb_run.py:_console_start():1827] atexit reg
2022-02-04 16:06:00,706 INFO    MainThread:5500 [wandb_run.py:_redirect():1701] redirect: SettingsConsole.WRAP
2022-02-04 16:06:00,707 INFO    MainThread:5500 [wandb_run.py:_redirect():1738] Wrapping output streams.
2022-02-04 16:06:00,708 INFO    MainThread:5500 [wandb_run.py:_redirect():1762] Redirects installed.
2022-02-04 16:06:00,709 INFO    MainThread:5500 [wandb_init.py:init():651] run started, returning control to user process
2022-02-04 16:06:00,709 INFO    MainThread:5500 [wandb_run.py:_config_callback():966] config_cb None None {'epochs': 5, 'batch_size': 1, 'learning_rate': 1e-05, 'val_percent': 0.1, 'save_checkpoint': True, 'img_scale': 0.5, 'amp': False}
2022-02-04 16:07:03,485 INFO    MainThread:5500 [wandb_run.py:_atexit_cleanup():1788] got exitcode: 1
2022-02-04 16:07:03,485 INFO    MainThread:5500 [wandb_run.py:_restore():1768] restore
2022-02-04 16:07:03,805 INFO    MainThread:5500 [wandb_run.py:_restore():1768] restore
2022-02-04 16:07:06,899 ERROR   MainThread:5500 [wandb_run.py:_atexit_cleanup():1788] Problem finishing run
Traceback (most recent call last):
  File "C:\Users\chank\anaconda3\envs\deep_learning\lib\site-packages\wandb\sdk\wandb_run.py", line 1788, in _atexit_cleanup
    def _atexit_cleanup(self, exit_code: int = None) -> None:
  File "C:\Users\chank\anaconda3\envs\deep_learning\lib\site-packages\wandb\sdk\wandb_run.py", line 1940, in _on_finish
    def _on_finish(self) -> None:
OSError: [Errno 22] Invalid argument
