INFO: Starting training:
        Epochs:          5
        Batch size:      1
        Learning rate:   1e-05
        Training size:   9000
        Validation size: 1000
        Checkpoints:     True
        Device:          cuda
        Images scaling:  0.5
        Mixed Precision: False
Epoch 1/5:   0%|                                                                                                                                               | 0/9000 [00:05<?, ?img/s]
Traceback (most recent call last):
  File "train.py", line 191, in <module>
    train_net(net=net,
  File "train.py", line 79, in train_net
    for batch in train_loader:
  File "C:\Users\yunjc\anaconda3\envs\dl_env\lib\site-packages\torch\utils\data\dataloader.py", line 521, in __next__
    data = self._next_data()
  File "C:\Users\yunjc\anaconda3\envs\dl_env\lib\site-packages\torch\utils\data\dataloader.py", line 1203, in _next_data
    return self._process_data(data)
  File "C:\Users\yunjc\anaconda3\envs\dl_env\lib\site-packages\torch\utils\data\dataloader.py", line 1229, in _process_data
    data.reraise()
  File "C:\Users\yunjc\anaconda3\envs\dl_env\lib\site-packages\torch\_utils.py", line 434, in reraise
    raise exception
AssertionError: Caught AssertionError in DataLoader worker process 0.
Original Traceback (most recent call last):
  File "C:\Users\yunjc\anaconda3\envs\dl_env\lib\site-packages\torch\utils\data\_utils\worker.py", line 287, in _worker_loop
    data = fetcher.fetch(index)
  File "C:\Users\yunjc\anaconda3\envs\dl_env\lib\site-packages\torch\utils\data\_utils\fetch.py", line 49, in fetch
    data = [self.dataset[idx] for idx in possibly_batched_index]
  File "C:\Users\yunjc\anaconda3\envs\dl_env\lib\site-packages\torch\utils\data\_utils\fetch.py", line 49, in <listcomp>
    data = [self.dataset[idx] for idx in possibly_batched_index]
  File "C:\Users\yunjc\anaconda3\envs\dl_env\lib\site-packages\torch\utils\data\dataset.py", line 363, in __getitem__
    return self.dataset[self.indices[idx]]
  File "C:\Users\yunjc\_python_jupyter\bupyeonggu\bp_road_crack_detection\_model_test\Pytorch-UNet-master\utils\crack_data_loading.py", line 106, in __getitem__
    assert img.size == annot.size, \
AssertionError: 이미지와 어노테이션의 V2F_HY_7786_20210114_100610_N_CH1_Seoul_Sun_Mainroad_Day_84024은 반드시 같아야 합니다, 지금은 이미지 (1280, 720) 와 어노테이션 921600로 다릅니다.